Workbook
Name Z_578704EF_7FEB_466F_8696_9E38F7D13393_.wvu.Cols: Planejamento!$M:$IM
Name Z_578704EF_7FEB_466F_8696_9E38F7D13393_.wvu.Cols: Proposta!$I:$IX
Name Z_578704EF_7FEB_466F_8696_9E38F7D13393_.wvu.PrintArea: Planejamento!$B$2:$H$51
Name Z_578704EF_7FEB_466F_8696_9E38F7D13393_.wvu.PrintArea: Proposta!$A$2:$H$201

Sheet Proposta
G2: =TODAY() -> 45850 | H2: 4ª Proposta
G4: Cliente: | H4: Marlisson
G5: Proposta: | H5: 20250520
B8: DOCUMENTOS E EXIGÊNCIAS LEGAIS | F8: =H8*100/(G199) -> 3.6068813 | G8: % | H8: =SUM(H12:H16) -> 1032.3124
E10: m² | ml | unid. | F10: quant.
B12: =Planejamento!B3 -> Projeto Arquitetonito para Liberação da Obra | E12: =Planejamento!C3 -> m² | F12: =Planejamento!D3 -> 0 | H12: =Planejamento!N3 -> 0
B14: =Planejamento!B4 -> Anotação de Responsabilidade Técnica (RRT) | E14: =Planejamento!C4 -> m² | F14: =Planejamento!D4 -> 36 | H14: =Planejamento!N4 -> 1032.3124
B15: =Planejamento!B5 -> Impressões | E15: =Planejamento!C5 -> unidade | F15: =Planejamento!D5 -> 0 | H15: =Planejamento!N5 -> 0
B16: =Planejamento!B6 -> Seguro de Obra | E16: =Planejamento!C6 -> m² | F16: =Planejamento!D6 -> 0 | H16: =Planejamento!N6 -> 0
B18: STAFF | F18: =H18*100/(G199) -> 2.9850052 | G18: % | H18: =SUM(H22:H26) -> 854.32752
E20: m² | ml | unid. | F20: quant.
B22: =Planejamento!B7 -> arquiteto | E22: =Planejamento!C7 -> hora | F22: =Planejamento!D7 -> 0 | H22: =Planejamento!N7 -> 0
B23: =Planejamento!B8 -> ajudante | E23: =Planejamento!C8 -> unidade | F23: =Planejamento!D8 -> 0 | H23: =Planejamento!N8 -> 0
B24: =Planejamento!B9 -> encarregado | E24: =Planejamento!C9 -> unidade | F24: =Planejamento!D9 -> 0 | H24: =Planejamento!N9 -> 0
B25: =Planejamento!B10 -> engenheiro | E25: =Planejamento!C10 -> unidade | F25: =Planejamento!D10 -> 0 | H25: =Planejamento!N10 -> 0
B26: =Planejamento!B11 -> limpeza recorrente | E26: =Planejamento!C11 -> unidade | F26: =Planejamento!D11 -> 36 | H26: =Planejamento!N11 -> 854.32752
B28: SERVIÇOS PRELIMINARES | F28: =H28*100/(G199) -> 5.1132034 | G28: % | H28: =SUM(H32:H45) -> 1463.4314
E30: m² | ml | unid. | F30: quant.
B32: =Planejamento!B12 -> saco para entulho* | E32: =Planejamento!C12 -> unidade | F32: =Planejamento!D12 -> 0 | H32: =Planejamento!N12 -> 0
B33: =Planejamento!B13 -> demolição de alvenaria | E33: =Planejamento!C13 -> m² | F33: =Planejamento!D13 -> 0 | H33: =Planejamento!N13 -> 0
B34: =Planejamento!B14 -> demolição e remocação de teto drywall | E34: =Planejamento!C14 -> m² | F34: =Planejamento!D14 -> 0 | H34: =Planejamento!N14 -> 0
B35: =Planejamento!B15 -> equipe para retirada de entulho | E35: =Planejamento!C15 -> unidade | F35: =Planejamento!D15 -> 36 | H35: =Planejamento!N15 -> 1067.9094
B36: =Planejamento!B16 -> caçamba de entulho* | E36: =Planejamento!C16 -> unidade | F36: =Planejamento!D16 -> 0 | H36: =Planejamento!N16 -> 0
B37: =Planejamento!B17 -> remoção de pisos | E37: =Planejamento!C17 -> unidade | F37: =Planejamento!D17 -> 0 | H37: =Planejamento!N17 -> 0
B38: =Planejamento!B18 -> remoção de caxilhos e portas | E38: =Planejamento!C18 -> unidade | F38: =Planejamento!D18 -> 0 | H38: =Planejamento!N18 -> 0
B39: =Planejamento!B19 -> remoções de portas e batentes | E39: =Planejamento!C19 -> unidade | F39: =Planejamento!D19 -> 0 | H39: =Planejamento!N19 -> 0
B40: =Planejamento!B20 -> remoção de bancada de cozinha | E40: =Planejamento!C20 -> unidade | F40: =Planejamento!D20 -> 1 | H40: =Planejamento!N20 -> 197.761
B41: =Planejamento!B21 -> remoção de tanque | E41: =Planejamento!C21 -> unidade | F41: =Planejamento!D21 -> 0 | H41: =Planejamento!N21 -> 0
B42: =Planejamento!B22 -> remoção de bacias sanitárias | E42: =Planejamento!C22 -> unidade | F42: =Planejamento!D22 -> 0 | H42: =Planejamento!N22 -> 0
B43: =Planejamento!B23 -> remoção de torneira | E43: =Planejamento!C23 -> unidade | F43: =Planejamento!D23 -> 0 | H43: =Planejamento!N23 -> 0
... B45: =Planejamento!B25 -> armários com descarte | E45: =Planejamento!C25 -> unidade | F45: =Planejamento!D25 -> 0 | H45: =Planejamento!N25 -> 0
B47: AR CONDICONADO | F47: =H47*100/(G199) -> 13.128495 | G47: % | H47: =SUM(H51:H54) -> 3757.459
E49: m² | ml | unid. | F49: quant.
B51: =Planejamento!B26 -> tubulação para equipamentos de 9 mil a 12 mil btus | E51: =Planejamento!C26 -> ml | F51: =Planejamento!D26 -> 10 | H51: =Planejamento!N26 -> 2768.654
B52: =Planejamento!B27 -> tubulação para equipamentos de 18 mil a 24 mil btus | E52: =Planejamento!C27 -> ml | F52: =Planejamento!D27 -> 0 | H52: =Planejamento!N27 -> 0
B53: =Planejamento!B28 -> drenos | E53: =Planejamento!C28 -> unidade | F53: =Planejamento!D28 -> 1 | H53: =Planejamento!N28 -> 395.522
B54: =Planejamento!B29 -> acoplamento dos equipamentos | E54: =Planejamento!C29 -> unidade | F54: =Planejamento!D29 -> 1 | H54: =Planejamento!N29 -> 593.283
B56: ELÉTRICA | F56: =H56*100/(G199) -> 6.4951502 | G56: % | H56: =SUM(H60:H77) -> 1858.9534
E58: m² | ml | unid. | F58: quant.
B60: =Planejamento!B30 -> alteração de quadro elétrico | E60: =Planejamento!C30 -> unidade | F60: =Planejamento!D30 -> 0 | H60: =Planejamento!N30 -> 0
...

Sheet Planejamento
D1: Venda | G1: Imposto | H1: Venda | I1: Compra
A2: Categoria | B2: Itens _ Descritivos | C2: m² | ml | unid. | hora | D2: Quant. | E2: Custo | F2: Quat.XCusto | G2: 0.1633 | H2: C/ Imposto | I2: Quant. | J2: Custo | K2: Total | L2: Rentabilidade | M2: 0.7 | N2: valor final
A3: Documentação | B3: Projeto Arquitetonito para Liberação da Obra | C3: m² | D3: 0 | E3: 40 | F3: =D3*E3 -> 0 | G3: =G2 -> 0.1633 | H3: =(F3*G3)+F3 -> 0 | I3: 0 | J3: 3 | K3: =I3*J3 -> 0 | L3: =N3-K3 -> 0 | M3: 0.1 | N3: =H3*M3+H3 -> 0
A4: Documentação | B4: Anotação de Responsabilidade Técnica (RRT) | C4: m² | D4: 36 | E4: 14.5 | F4: =D4*E4 -> 522 | G4: =G3 -> 0.1633 | H4: =(F4*G4)+F4 -> 607.2426 | I4: 1 | J4: 500 | K4: =I4*J4 -> 500 | L4: =N4-K4 -> 532.31242 | M4: =M2 -> 0.7 | N4: =H4*M4+H4 -> 1032.3124 | O4: =L4*1/N4 -> 0.5156505
A5: Documentação | B5: Impressões | C5: unidade | D5: 0 | E5: 3 | F5: =D5*E5 -> 0 | G5: =G4 -> 0.1633 | H5: =(F5*G5)+F5 -> 0 | I5: 0 | J5: 0 | K5: =I5*J5 -> 0 | L5: =N5-K5 -> 0 | M5: =M2 -> 0.7 | N5: =H5*M5+H5 -> 0
A6: Documentação | B6: Seguro de Obra | C6: m² | D6: 0 | E6: 8 | F6: =D6*E6 -> 0 | G6: =G5 -> 0.1633 | H6: =(F6*G6)+F6 -> 0 | I6: 0 | J6: 0 | K6: =I6*J6 -> 0 | L6: =N6-K6 -> 0 | M6: =M5 -> 0.7 | N6: =H6*M6+H6 -> 0
A7: Staff | B7: arquiteto | C7: hora | D7: 0 | E7: 110 | F7: =D7*E7 -> 0 | G7: =G6 -> 0.1633 | H7: =(F7*G7)+F7 -> 0 | I7: 0 | J7: 0 | K7: =I7*J7 -> 0 | L7: =N7-K7 -> 0 | M7: =M6 -> 0.7 | N7: =H7*M7+H7 -> 0
A8: Staff | B8: ajudante | C8: unidade | D8: 0 | E8: 80 | F8: =D8*E8 -> 0 | G8: =G7 -> 0.1633 | H8: =(F8*G8)+F8 -> 0 | I8: 0 | J8: 0 | K8: =I8*J8 -> 0 | L8: =N8-K8 -> 0 | M8: =M7 -> 0.7 | N8: =H8*M8+H8 -> 0
A9: Staff | B9: encarregado | C9: unidade | D9: 0 | E9: 40 | F9: =D9*E9 -> 0 | G9: =G8 -> 0.1633 | H9: =(F9*G9)+F9 -> 0 | I9: 0 | J9: 0 | K9: =I9*J9 -> 0 | L9: =N9-K9 -> 0 | M9: =M8 -> 0.7 | N9: =H9*M9+H9 -> 0
A10: Staff | B10: engenheiro | C10: unidade | D10: 0 | E10: 150 | F10: =D10*E10 -> 0 | G10: =G9 -> 0.1633 | H10: =(F10*G10)+F10 -> 0 | I10: 0 | J10: 0 | K10: =I10*J10 -> 0 | L10: =N10-K10 -> 0 | M10: =M9 -> 0.7 | N10: =H10*M10+H10 -> 0
A11: Staff | B11: limpeza recorrente | C11: unidade | D11: 36 | E11: 12 | F11: =D11*E11 -> 432 | G11: =G10 -> 0.1633 | H11: =(F11*G11)+F11 -> 502.5456 | I11: 0 | J11: 0 | K11: =I11*J11 -> 0 | L11: =N11-K11 -> 854.32752 | M11: =M10 -> 0.7 | N11: =H11*M11+H11 -> 854.32752 | O11: =L11*1/N11 -> 1
A12: Demolições | B12: saco para entulho* | C12: unidade | D12: 0 | E12: 2.5 | F12: =D12*E12 -> 0 | G12: =G11 -> 0.1633 | H12: =(F12*G12)+F12 -> 0 | I12: 0 | J12: 0 | K12: =I12*J12 -> 0 | L12: =N12-K12 -> 0 | M12: =M11 -> 0.7 | N12: =H12*M12+H12 -> 0
A13: Demolições | B13: demolição de alvenaria | C13: m² | D13: 0 | E13: 25 | F13: =D13*E13 -> 0 | G13: =G12 -> 0.1633 | H13: =(F13*G13)+F13 -> 0 | I13: 0 | J13: 0 | K13: =I13*J13 -> 0 | L13: =N13-K13 -> 0 | M13: =M12 -> 0.7 | N13: =H13*M13+H13 -> 0
A14: Demolições | B14: demolição e remocação de teto drywall | C14: m² | D14: 0 | E14: 45 | F14: =D14*E14 -> 0 | G14: =G13 -> 0.1633 | H14: =(F14*G14)+F14 -> 0 | I14: 0 | J14: 0 | K14: =I14*J14 -> 0 | L14: =N14-K14 -> 0 | M14: =M13 -> 0.7 | N14: =H14*M14+H14 -> 0
A15: Demolições | B15: equipe para retirada de entulho | C15: unidade | D15: 36 | E15: 15 | F15: =D15*E15 -> 540 | G15: =G14 -> 0.1633 | H15: =(F15*G15)+F15 -> 628.182 | I15: 0 | J15: 0 | K15: =I15*J15 -> 0 | L15: =N15-K15 -> 1067.9094 | M15: =M14 -> 0.7 | N15: =H15*M15+H15 -> 1067.9094 | O15: =L15*1/N15 -> 1
A16: Demolições | B16: caçamba de entulho* | C16: unidade | D16: 0 | E16: 300 | F16: =D16*E16 -> 0 | G16: =G15 -> 0.1633 | H16: =(F16*G16)+F16 -> 0 | I16: 0 | J16: 0 | K16: =I16*J16 -> 0 | L16: =N16-K16 -> 0 | M16: =M15 -> 0.7 | N16: =H16*M16+H16 -> 0
A17: remoções | B17: remoção de pisos | C17: unidade | D17: 0 | E17: 20 | F17: =D17*E17 -> 0 | G17: =G16 -> 0.1633 | H17: =(F17*G17)+F17 -> 0 | I17: 0 | J17: 0 | K17: =I17*J17 -> 0 | L17: =N17-K17 -> 0 | M17: =M16 -> 0.7 | N17: =H17*M17+H17 -> 0
A18: remoções | B18: remoção de caxilhos e portas | C18: unidade | D18: 0 | E18: 100 | F18: =D18*E18 -> 0 | G18: =G17 -> 0.1633 | H18: =(F18*G18)+F18 -> 0 | I18: 0 | J18: 0 | K18: =I18*J18 -> 0 | L18: =N18-K18 -> 0 | M18: =M17 -> 0.7 | N18: =H18*M18+H18 -> 0
A19: remoções | B19: remoções de portas e batentes | C19: unidade | D19: 0 | E19: 50 | F19: =D19*E19 -> 0 | G19: =G18 -> 0.1633 | H19: =(F19*G19)+F19 -> 0 | I19: 0 | J19: 0 | K19: =I19*J19 -> 0 | L19: =N19-K19 -> 0 | M19: =M18 -> 0.7 | N19: =H19*M19+H19 -> 0
A20: Remoções | B20: remoção de bancada de cozinha | C20: unidade | D20: 1 | E20: 100 | F20: =D20*E20 -> 100 | G20: =G19 -> 0.1633 | H20: =(F20*G20)+F20 -> 116.33 | I20: 0 | J20: 0 | K20: =I20*J20 -> 0 | L20: =N20-K20 -> 197.761 | M20: =M19 -> 0.7 | N20: =H20*M20+H20 -> 197.761 | O20: =L20*1/N20 -> 1
A21: Remoções | B21: remoção de tanque | C21: unidade | D21: 0 | E21: 40 | F21: =D21*E21 -> 0 | G21: =G20 -> 0.1633 | H21: =(F21*G21)+F21 -> 0 | I21: 0 | J21: 0 | K21: =I21*J21 -> 0 | L21: =N21-K21 -> 0 | M21: =M20 -> 0.7 | N21: =H21*M21+H21 -> 0
A22: Remoções | B22: remoção de bacias sanitárias | C22: unidade | D22: 0 | E22: 40 | F22: =D22*E22 -> 0 | G22: =G21 -> 0.1633 | H22: =(F22*G22)+F22 -> 0 | I22: 0 | J22: 0 | K22: =I22*J22 -> 0 | L22: =N22-K22 -> 0 | M22: =M21 -> 0.7 | N22: =H22*M22+H22 -> 0
A23: Remoções | B23: remoção de torneira | C23: unidade | D23: 0 | E23: 20 | F23: =D23*E23 -> 0 | G23: =G22 -> 0.1633 | H23: =(F23*G23)+F23 -> 0 | I23: 0 | J23: 0 | K23: =I23*J23 -> 0 | L23: =N23-K23 -> 0 | M23: =M22 -> 0.7 | N23: =H23*M23+H23 -> 0
A24: Remoções | B24: remoção de bancada de banheiro | C24: unidade | D24: 1 | E24: 100 | F24: =D24*E24 -> 100 | G24: =G23 -> 0.1633 | H24: =(F24*G24)+F24 -> 116.33 | I24: 0 | J24: 0 | K24: =I24*J24 -> 0 | L24: =N24-K24 -> 197.761 | M24: =M23 -> 0.7 | N24: =H24*M24+H24 -> 197.761 | O24: =L24*1/N24 -> 1
A25: Remoções | B25: armários com descarte | C25: unidade | D25: 0 | E25: 150 | F25: =D25*E25 -> 0 | G25: =G24 -> 0.1633 | H25: =(F25*G25)+F25 -> 0 | I25: 0 | J25: 0 | K25: =I25*J25 -> 0 | L25: =N25-K25 -> 0 | M25: =M24 -> 0.7 | N25: =H25*M25+H25 -> 0
A26: Infra Ar | B26: tubulação para equipamentos de 9 mil a 12 mil btus | C26: ml | D26: 10 | E26: 140 | F26: =D26*E26 -> 1400 | G26: =G25 -> 0.1633 | H26: =(F26*G26)+F26 -> 1628.62 | I26: 1 | J26: 800 | K26: =I26*J26 -> 800 | L26: =N26-K26 -> 1968.654 | M26: =M25 -> 0.7 | N26: =H26*M26+H26 -> 2768.654 | O26: =L26*1/N26 -> 0.71105093
A27: Infra Ar | B27: tubulação para equipamentos de 18 mil a 24 mil btus | C27: ml | D27: 0 | E27: 160 | F27: =D27*E27 -> 0 | G27: =G26 -> 0.1633 | H27: =(F27*G27)+F27 -> 0 | I27: 0 | J27: 0 | K27: =I27*J27 -> 0 | L27: =N27-K27 -> 0 | M27: =M26 -> 0.7 | N27: =H27*M27+H27 -> 0
A28: Infra Ar | B28: drenos | C28: unidade | D28: 1 | E28: 200 | F28: =D28*E28 -> 200 | G28: =G27 -> 0.1633 | H28: =(F28*G28)+F28 -> 232.66 | I28: 1 | J28: 150 | K28: =I28*J28 -> 150 | L28: =N28-K28 -> 245.522 | M28: =M27 -> 0.7 | N28: =H28*M28+H28 -> 395.522 | O28: =L28*1/N28 -> 0.62075434
A29: Infra Ar | B29: acoplamento dos equipamentos | C29: unidade | D29: 1 | E29: 300 | F29: =D29*E29 -> 300 | G29: =G28 -> 0.1633 | H29: =(F29*G29)+F29 -> 348.99 | I29: 1 | J29: 150 | K29: =I29*J29 -> 150 | L29: =N29-K29 -> 443.283 | M29: =M28 -> 0.7 | N29: =H29*M29+H29 -> 593.283 | O29: =L29*1/N29 -> 0.74716956
A30: Elétrica | B30: alteração de quadro elétrico | C30: unidade | D30: 0 | E30: 300 | F30: =D30*E30 -> 0 | G30: =G29 -> 0.1633 | H30: =(F30*G30)+F30 -> 0 | I30: 0 | J30: 0 | K30: =I30*J30 -> 0 | L30: =N30-K30 -> 0 | M30: =M29 -> 0.7 | N30: =H30*M30+H30 -> 0
A31: Elétrica | B31: instalação de balizador | C31: unidade | D31: 0 | E31: 40 | F31: =D31*E31 -> 0 | G31: =G30 -> 0.1633 | H31: =(F31*G31)+F31 -> 0 | I31: 0 | J31: 0 | K31: =I31*J31 -> 0 | L31: =N31-K31 -> 0 | M31: =M30 -> 0.7 | N31: =H31*M31+H31 -> 0
A32: Elétrica | B32: instalação de fita de led | C32: unidade | D32: 0 | E32: 60 | F32: =D32*E32 -> 0 | G32: =G31 -> 0.1633 | H32: =(F32*G32)+F32 -> 0 | I32: 0 | J32: 0 | K32: =I32*J32 -> 0 | L32: =N32-K32 -> 0 | M32: =M31 -> 0.7 | N32: =H32*M32+H32 -> 0
A33: Elétrica | B33: instalação de luminárias especiais | C33: unidade | D33: 0 | E33: 40 | F33: =D33*E33 -> 0 | G33: =G32 -> 0.1633 | H33: =(F33*G33)+F33 -> 0 | I33: 0 | J33: 0 | K33: =I33*J33 -> 0 | L33: =N33-K33 -> 0 | M33: =M32 -> 0.7 | N33: =H33*M33+H33 -> 0
A34: Elétrica | B34: instalação de lustre | C34: unidade | D34: 0 | E34: 40 | F34: =D34*E34 -> 0 | G34: =G33 -> 0.1633 | H34: =(F34*G34)+F34 -> 0 | I34: 0 | J34: 0 | K34: =I34*J34 -> 0 | L34: =N34-K34 -> 0 | M34: =M33 -> 0.7 | N34: =H34*M34+H34 -> 0
A35: Elétrica | B35: instalação de pendente | C35: unidade | D35: 0 | E35: 50 | F35: =D35*E35 -> 0 | G35: =G34 -> 0.1633 | H35: =(F35*G35)+F35 -> 0 | I35: 0 | J35: 0 | K35: =I35*J35 -> 0 | L35: =N35-K35 -> 0 | M35: =M34 -> 0.7 | N35: =H35*M35+H35 -> 0
A36: Elétrica | B36: interruptor intermediário | C36: unidade | D36: 0 | E36: 40 | F36: =D36*E36 -> 0 | G36: =G35 -> 0.1633 | H36: =(F36*G36)+F36 -> 0 | I36: 0 | J36: 0 | K36: =I36*J36 -> 0 | L36: =N36-K36 -> 0 | M36: =M35 -> 0.7 | N36: =H36*M36+H36 -> 0
A37: Elétrica | B37: interruptor paralelo | C37: unidade | D37: 0 | E37: 30 | F37: =D37*E37 -> 0 | G37: =G36 -> 0.1633 | H37: =(F37*G37)+F37 -> 0 | I37: 0 | J37: 0 | K37: =I37*J37 -> 0 | L37: =N37-K37 -> 0 | M37: =M36 -> 0.7 | N37: =H37*M37+H37 -> 0
A38: Elétrica | B38: interruptor simples | C38: unidade | D38: 0 | E38: 25 | F38: =D38*E38 -> 0 | G38: =G37 -> 0.1633 | H38: =(F38*G38)+F38 -> 0 | I38: 0 | J38: 0 | K38: =I38*J38 -> 0 | L38: =N38-K38 -> 0 | M38: =M37 -> 0.7 | N38: =H38*M38+H38 -> 0
A39: Elétrica | B39: ponto de balizador | C39: unidade | D39: 0 | E39: 40 | F39: =D39*E39 -> 0 | G39: =G38 -> 0.1633 | H39: =(F39*G39)+F39 -> 0 | I39: 0 | J39: 0 | K39: =I39*J39 -> 0 | L39: =N39-K39 -> 0 | M39: =M38 -> 0.7 | N39: =H39*M39+H39 -> 0
A40: Elétrica | B40: ponto de energia para motorização | C40: unidade | D40: 0 | E40: 40 | F40: =D40*E40 -> 0 | G40: =G39 -> 0.1633 | H40: =(F40*G40)+F40 -> 0 | I40: 0 | J40: 0 | K40: =I40*J40 -> 0 | L40: =N40-K40 -> 0 | M40: =M39 -> 0.7 | N40: =H40*M40+H40 -> 0
...

Sheet Piso Vinilico 
L2: Unid. | M2: Quant. | N2: Caixas | O2: Valor | P2: Total
C3: Piso Vinilico: | D3: Angelin Pedra | K3: PISO LVT AGIFLOOR VINILICO (3.0 MM) (0,50MM) 3,611 M2 - 8010 ANGELIN PEDRA NEW 18,5 X 122 | L3: M² | M3: 32.499 | N3: 9 | O3: 75.15 | P3: =M3*O3 -> 2442.2999
K4: ADESIVO AGI 4 KG | L4: Kg | M4: 12 | N4: 3 | O4: 29.88 | P4: =M4*O4 -> 358.56
C5: Ambiente | D5: Medida | F5: m² | K5: Cola HOMESTAR Nova Formula 1 kg | L5: Unid. | M5: 2 | N5: 2 | O5: 26.5 | P5: =M5*O5 -> 53
K6: RODAPE 15 CM 2,16 ML - BRANCO MAX FRISADO | L6: ml | M6: 17.28 | N6: 8 | O6: 19.53 | P6: =M6*O6 -> 337.4784
C7: Sala | D7: 2.45 | E7: 4.55 | F7: =D7*E7 -> 11.1475 | P7: =SUM(P3:P6) -> 3191.3383
C8: Dorm 1 | D8: 4 | E8: 2.5 | F8: =D8*E8 -> 10 | K8: frete | P8: =176.99+40 -> 216.99
C9: Dorm 2 | D9: 2 | E9: 2.65 | F9: =D9*E9 -> 5.3 | K9: instalação piso | L9: m² | M9: 25 | O9: 20 | P9: =M9*O9 -> 500
E10: Total | F10: =SUM(F7:F9) -> 26.4475 | K10: instalação rodapé | M10: 10 | O10: 11 | P10: =M10*O10 -> 110
F11: 0.1
F12: =F10*F11+F10 -> 29.09225 | H12: 72.9 | I12: =F12*H12 -> 2120.825 | P12: =SUM(P7:P10) -> 4018.3283
P13: =P12/32.5 -> 123.64087
C14: Cola Piso | D14: R$
K15: Cobrar Diferença do Cliente R$ 337,48
C18: Rodapé: | D18: branco 15cm
D19: Medida Linear | F19: ML
C20: Total | F20: =17.64-3 -> 14.64
F21: 0.1
F22: =F20*F21+F20 -> 16.104
C24: Fixadores | D24: R$
C25: Cola | D25: R$
C28: Mão de Obra
E29: Piso | F29: Rodapé
C30: Instalação

Sheet Extras
D4: Marmoraria
A5: Não foi vendido pintura para o cliente
A6: Orçar pintura
A7: Orçar Cotineiro de gesso
A9: Shaft para esconder tubulações | B9: 550
